Workbook
Name _xlfn.IFERROR: #NAME?

Sheet D40
L5: CATEGORÍA: DAMAS 5TA
D16: 1° A | E16: =+IFERROR(VLOOKUP(D16,'Base D40'!$B$3:$D$47,2,0)," ") -> LIBERTINI
E17: =+IFERROR(VLOOKUP(D16,'Base D40'!$B$3:$D$47,3,0)," ") -> L. BENITEZ
B20: 2° J | C20: =+IFERROR(VLOOKUP(B20,'Base D40'!$B$3:$D$47,2,0)," ") -> ISOLDI | E20: 49 | F20: =+IFERROR(VLOOKUP(#REF!,'Base D40'!$B$3:$D$47,2,0)," ")
C21: =+IFERROR(VLOOKUP(B20,'Base D40'!$B$3:$D$47,3,0)," ") -> T. PEREZ
C24: 35 | D24: =+IFERROR(VLOOKUP(#REF!,'Base D40'!$B$3:$D$47,2,0)," ")
B28: 2° K | C28: =+IFERROR(VLOOKUP(B28,'Base D40'!$B$3:$D$47,2,0)," ") -> J. ALVAREZ
C29: =+IFERROR(VLOOKUP(B28,'Base D40'!$B$3:$D$47,3,0)," ") -> L. CARDINALI
G30: 57 | H30: =+IFERROR(VLOOKUP($G$36,'Base D40'!$B$3:$D$47,2,0)," ")
B32: 1° I | C32: =+IFERROR(VLOOKUP(B32,'Base D40'!$B$3:$D$47,2,0)," ") -> ROSSETO
C33: =+IFERROR(VLOOKUP(B32,'Base D40'!$B$3:$D$47,3,0)," ") -> PECCI
C36: 36 | D36: =+IFERROR(VLOOKUP(#REF!,'Base D40'!$B$3:$D$47,2,0)," ")
B40: 2° C | C40: =+IFERROR(VLOOKUP(B40,'Base D40'!$B$3:$D$47,2,0)," ") -> SISTERNA | E40: 50 | F40: =+IFERROR(VLOOKUP(#REF!,'Base D40'!$B$3:$D$47,2,0)," ")
C41: =+IFERROR(VLOOKUP(B40,'Base D40'!$B$3:$D$47,3,0)," ") -> CORONEL
B46: 2° B | C46: =+IFERROR(VLOOKUP(B46,'Base D40'!$B$3:$D$47,2,0)," ") -> CONCA
C47: =+IFERROR(VLOOKUP(B46,'Base D40'!$B$3:$D$47,3,0)," ") -> FEJMI
C50: 37 | D50: =+IFERROR(VLOOKUP(#REF!,'Base D40'!$B$3:$D$47,2,0)," ")
H53: 61
B54: 1° H | C54: =+IFERROR(VLOOKUP(B54,'Base D40'!$B$3:$D$47,2,0)," ") -> PRIETO
C55: =+IFERROR(VLOOKUP(B54,'Base D40'!$B$3:$D$47,3,0)," ") -> DAQUILA
D58: 1° E | E58: =+IFERROR(VLOOKUP(D58,'Base D40'!$B$3:$D$47,2,0)," ") -> I. BRAVO
E59: =+IFERROR(VLOOKUP(D58,'Base D40'!$B$3:$D$47,3,0)," ") -> G. PRADO
B62: 2° F | C62: =+IFERROR(VLOOKUP(B62,'Base D40'!$B$3:$D$47,2,0)," ") -> GALLEGUILLO | E62: 51 | F62: =+IFERROR(VLOOKUP(#REF!,'Base D40'!$B$3:$D$47,2,0)," ")
C63: =+IFERROR(VLOOKUP(B62,'Base D40'!$B$3:$D$47,3,0)," ") -> L. BRAVO
C66: 37 | D66: =+IFERROR(VLOOKUP(#REF!,'Base D40'!$B$3:$D$47,2,0)," ")
B70: 1° L | C70: =+IFERROR(VLOOKUP(B70,'Base D40'!$B$3:$D$47,2,0)," ") -> SACARELO
C71: =+IFERROR(VLOOKUP(B70,'Base D40'!$B$3:$D$47,3,0)," ") -> BURZAN
G74: 58
B77: 1° M | C77: =+IFERROR(VLOOKUP(B77,'Base D40'!$B$3:$D$47,2,0)," ") -> M. GONZALEZ
C78: =+IFERROR(VLOOKUP(B77,'Base D40'!$B$3:$D$47,3,0)," ") -> REGUEIRA
C81: 39 | D81: =+IFERROR(VLOOKUP(#REF!,'Base D40'!$B$3:$D$47,2,0)," ")
B85: 2° G | C85: =+IFERROR(VLOOKUP(B85,'Base D40'!$B$3:$D$47,2,0)," ") -> FURLANI | E85: 52 | F85: =+IFERROR(VLOOKUP(#REF!,'Base D40'!$B$3:$D$47,2,0)," ")
C86: =+IFERROR(VLOOKUP(B85,'Base D40'!$B$3:$D$47,3,0)," ") -> DE JESUS REY
D89: 1° D | E89: =+IFERROR(VLOOKUP(D89,'Base D40'!$B$3:$D$47,2,0)," ") -> SIMONETTI
E90: =+IFERROR(VLOOKUP(D89,'Base D40'!$B$3:$D$47,3,0)," ") -> SAUREL
I92: 64
D98: 1° C | E98: =+IFERROR(VLOOKUP(D98,'Base D40'!$B$3:$D$47,2,0)," ") -> IRRAZABAL
E99: =+IFERROR(VLOOKUP(D98,'Base D40'!$B$3:$D$47,3,0)," ") -> ROMERO
B102: 2° H | C102: =+IFERROR(VLOOKUP(B102,'Base D40'!$B$3:$D$47,2,0)," ") -> RICCIO | E102: 53
C103: =+IFERROR(VLOOKUP(B102,'Base D40'!$B$3:$D$47,3,0)," ") -> ITURRIZA
...

Sheet Base D40
B1: PUESTO X ZONA | C1: APELLIDOS JUGADOR | D1: APELLIDOS JUGADOR
B3: 1° A | C3: LIBERTINI | D3: L. BENITEZ
B4: 2° A | C4: MENDEZ | D4: SOSA
B5: 3° A | C5: FREZZA | D5: TOUCEDA
B6: 1° B | C6: LOREFICE | D6: REYNOSO
B7: 2° B | C7: CONCA | D7: FEJMI
B8: 1° C | C8: IRRAZABAL | D8: ROMERO
B9: 2° C | C9: SISTERNA | D9: CORONEL
B10: 1° D | C10: SIMONETTI | D10: SAUREL
B11: 2° D | C11: SANDOVAL | D11: SILVA
B12: 1° E | C12: I. BRAVO | D12: G. PRADO
B13: 2° E | C13: CASTILLO | D13: ESPINDOLA
... B29: 2° M | C29: F. ROMERO | D29: L. GONZALEZ
B31: COMPLEJO
B32: LA BARRA
B33: VIDA VIVA
B34: EL PORTAL
B36: DIA-HORA
B37: VIERNES 09:15 hs
B38: VIERNES 09:30 hs
B39: VIERNES 09:45 hs
B40: VIERNES 10:00 hs
B41: VIERNES 10:15 hs
B42: VIERNES 10:30 hs
B43: VIERNES 10:45 hs
... B213: DOMINGO 23:45 hs
